## Исключения

Виды ошибок:
* Ошибки по вине программиста. Например:
```c++
1. char *s = NULL;
   size_t l = strlen(s);

2. Array a(-1)
```
Обработка таких ошибок:
1. Лучше выявить на стадии тестирования (assert, unit test, etc)
2. При выполнении "идеальной программы" их не происходит 
3. Библиотека C подобные ошибки не обрабатывает 
4. Библиотека C++ - по-разному в разных местах 
5. Обрабатывать их или нет - на усмотрение программиста
  
* Ошибки по вине окружения программы:
1. Файл не существует
2. Сервер разорвал сетевое соединение
3. Пользователь вместо числа ввел букву

Обработка таких ошибок:
1. Могут произойти и при выполнении идеальной программы
2. Обязательно надо обрабатывать!

### Обработка ошибок в стиле C

Обрабатываем по следующему алгоритму:
* Проверяем на наличие ошибки
* Освобождаем ресурсы
* Сообщаем пользователю или вызывающей функции об ошибке
* Предпринять действия по восстановлению от ошибки (например, не смогли соединиться - попробовать еще три раза)

Информацию об ошибке передаем через возвращаемое значение и глобальную переменную:
```c
FILE* fopen(...) {
    if (file_not_found) {
        errno = 666;
        return NULL;
    }
    if (permission_denied) {
        errno = 777;
        return NULL;
    }
    ...
}
```

Но в таком способе мало информации! Не знаем причину ошибки: нет файла, нет прав доступа, ...
Глобальная переменная хранит код ошибки, можно получить оттуда сообщение (`strerror(code)`) 

Но есть еще одна проблема: не всегда хватает диапазона возвращаемых значений функции:
```c++
class Array {
private:
    int *a;
public:
    // Пусть возвращает -1, когда индекс выходит за границу
    int get(size_t index);
};

int r1 = atoi("0");
int r2 = atoi("a"); // ?
```

Код логики и обработка ошибок перемешаны:
```c++
r = fread(...);
if (r < ...) {
    // error
}
r = fseek(...);
if (r != 0) {
    // error
}
```

### `try` / `catch` / `throw`
Пощупаем C++ - style:
```c++
class MyException {
private:
    char message[256];
public:
    const char* message();
};

double divide(int a, int b) {
    if (b == 0) {
        throw MyException("Division by zero");
    }
    return a / b;
}

int main() {
    try {
        x = divide(c, d);
    }
    catch (MyException& e) {
        std::cout << e.message();
    }
    return 0;
}
```

Поймать любое исключение можно так:
```c++
try {
    doMainWork();
}
catch(...) { // Ловим все, что угодно
    throw; // Кидаем все, что угодно
}
```
### Исключения в конструкторах и деструкторах

Допустим, произошло исключение в `divide`, объект не достроен. 

Деструкторы у недостроенных объектов не вызываются:

```c++
class PhoneBookItem {
    PhoneBookItem(const char *audio, const char *pic) {
        af = fopen(audio, "r");
        pf = fopen(pic, "r");
        divide(c, e); // Может выкинуть исключение в конструкторе
        f();
    }
    
    ~PhoneBookItem() {
        fclose(af);
        fclode(pf);
    }
};
```

Надо бы предусмотреть такую ситуацию:
```c++
class PhondeBookItem {
    PhoneBookItem(const char *audio, const char *pic) {
        try {
            af = fopen(audio, "r");
            pf= = fopen(pic, "r");
            divide(c, e); // Может кинуть исключение
            f();
        }
        
        catch (MyException& e) {
            fclose(af);
            fclose(pf);
            throw e; // Inform caller
        }
    }
};
```

Посмотрим на исключения в деструкторе:
Представим себе такую ситуацию: логи посылаются на сервер. За это отвечает объект `networkLogger`, методы которого могут бросать исключения:
```c++
class PersonDatabase {
    ~PersonDatabase() {
        // Кидает исключение если сервер недоступен
        networkLogger.log("Database is closed.")
        ...
    }
};

f() {
    PersonDatanase db;
    if (...) throw MyException("Error: disk is full.")
}
```

Есть проблема:
* Исключение от `networkLogger` может подменить исключение о том, что "места на диске больше нет", и мы не узнаем истинную причину ошибки
* Поэтому *КИДАТЬ ИСКЛЮЧЕНИЯ В ДЕСТРУКТОРАХ ЗАПРЕЩЕНО*!

Предусмотрим такую ситуацию:
```c++
class PersonDatabase {
    ~PersonDatabase() {
        try {
            // Кидает исключение если сервер недоступен
            networkLogger.log("Database is closed.")
            ...
        }
        catch(...) {...}
    }
}
```

### Идиома `RAII`: использование и примеры классов

Идиома `RAII`: `Resource Acquisition Is Initialization` (взятие ресурса должно происходить через инициализацию)

Т.е. взятие ресурса нужно "инкапсулировать" в класс, чтобы в случае исключения вызвался деструктор и освободил ресурс:

```c++
f() {
    MyArray buffer(n);
    if (...) throw MyException(...);
}

g() {
    unique_ptr p(new Person("Jenya", 36));
    divide(c, e) // Может кинуть исключение
}
```

### Гарантии исключений
Гарантии при работе с исключениями:
* Обязательства метода с точки зрения работы с исключениями
* Документация для программиста, работающего с методом

Виды гарантий:
* `no throw guarantee` - метод не бросает исключений вообще
Допустим у нас есть функция `safe_div`, не кидающая исключения:
```c++
void is_dividable(double a, double b) {
    try {
        divide(a, b); // Может выкинуть исключение
        std::cout << "Yes" << std::endl;
    } catch (...) {
        std::cout << "No" << std::endl;
    }
} 
```

* `basic guarantee` - в случае возникновения исключения ресурсы не утекают
Рассмотрим пример какого-то заполнения массив: если тут произойдет исключение, то память не утечет, но измененные элементы `array` свои значения не восстановят:
```c++
class PersonDatabase {
    MyVector<Person> array;
    void person_age_random_filling() {
        unique_ptr<Person> p(new Person(...));
        for (size_t i = 0; i < array.length; i++) {
            int age = divide( rand(), rand() ); // Может выпасть рандомно 0 в знаменателе и вылетит исключение
            array[i]->set_age(age);
        }
    }
};
```
* `strong guarantee` - переменны принимают те же значения, что были до возникновения ошибки

Доработаем пример выше: можно сделать "бэкап" нашего массива, и по успешном окончании свапнуть его с настоящим:
```c++
class PersonDatabase {
    MyVector<Person> array;
    
    void person_age_random_filling() {
        unique_ptr<Person> p(new Person(...));
        MyVector<Person> copy(array);
        for (size_t i = 0; i < array.length; i++) {
            int age = divide( rand(), rand() ); // Может выпасть рандомно 0 в знаменателе и вылетит исключение
            array[i]->set_age(age);
        }
        
        array.swap(copy);
    }
};
```